#VRML_SIM R2022b utf8

EXTERNPROTO "https://raw.githubusercontent.com/cyberbotics/webots/R2022b/projects/objects/backgrounds/protos/TexturedBackground.proto"
EXTERNPROTO "https://raw.githubusercontent.com/cyberbotics/webots/R2022b/projects/objects/backgrounds/protos/TexturedBackgroundLight.proto"
EXTERNPROTO "https://raw.githubusercontent.com/cyberbotics/webots/R2022b/projects/objects/factory/containers/protos/WoodenBox.proto"
EXTERNPROTO "https://raw.githubusercontent.com/cyberbotics/webots/R2022b/projects/robots/gctronic/e-puck/protos/E-puck.proto"
EXTERNPROTO "https://raw.githubusercontent.com/cyberbotics/webots/R2022b/projects/objects/floors/protos/Floor.proto"
EXTERNPROTO "https://raw.githubusercontent.com/cyberbotics/webots/R2022b/projects/appearances/protos/PerforatedMetal.proto"

WorldInfo {
  basicTimeStep 16
}
Viewpoint {
  orientation 0.2714040607133432 -0.451813905651659 -0.8498258824536361 4.982007687462586
  position -0.4958814517749588 -0.9889125990488024 0.8242096415755515
}
TexturedBackground {
}
TexturedBackgroundLight {
}
Floor {
  size 1 1
}
WoodenBox {
  translation -0.309635 -0.309901 0.05
  size 0.1 0.1 0.1
}
WoodenBox {
  translation -0.178622 0.312617 0.05
  name "wooden box(1)"
  size 0.1 0.1 0.1
}
WoodenBox {
  translation 0.184039 0.0654821 0.05
  name "wooden box(2)"
  size 0.1 0.1 0.1
}
E-puck {
  translation -0.454585 -0.0687101 0
  controller "epuck_go_forward"
}
E-puck {
  translation -0.38058 0.163306 4.66294e-15
  rotation 0 1 0 0
  name "e-puck_avoid_collision"
  controller "epuck_avoid_collision"
}
Solid {
  translation 0.0264465 0.268796 0.2
  rotation 0 1 0 0
  scale 0.5 0.5 0.5
  children [
    Shape {
      appearance PerforatedMetal {
      }
      geometry DEF BALL_GEOMETRY Sphere {
        radius 0.1
      }
    }
  ]
  name "1stball"
  boundingObject USE BALL_GEOMETRY
  physics Physics {
  }
}
Solid {
  translation 0.4 0.3 0.11
  scale 0.5 0.5 0.5
  children [
    Shape {
      appearance PBRAppearance {
        roughness 0.5
        metalness 0.5
      }
      geometry Sphere {
        radius 0.1
      }
    }
  ]
  name "2ndball"
  boundingObject Sphere {
    radius 0.1
  }
  physics Physics {
  }
}
Solid {
  translation 0 -0.5 0
  scale 0.2 0.2 0.2
  children [
    Shape {
      appearance DEF wallcolor PBRAppearance {
        baseColor 0.0392157 0.0392157 1
        roughness 1
        metalness 0
      }
      geometry Box {
        size 5 0.1 0.5
      }
    }
  ]
  name "wall"
}
Solid {
  translation 0 0.5 0
  scale 0.2 0.2 0.2
  children [
    Shape {
      appearance USE wallcolor
      geometry Box {
        size 5 0.1 0.5
      }
    }
  ]
  name "wall(3)"
}
Solid {
  translation 0.5 0 0
  rotation 0 0 1 1.5708
  scale 0.2 0.2 0.2
  children [
    Shape {
      appearance USE wallcolor
      geometry Box {
        size 5 0.1 0.5
      }
    }
  ]
  name "wall(1)"
}
Solid {
  translation -0.5 0 0.05
  rotation 0 0 1 1.5708
  scale 0.2 0.2 0.2
  children [
    Shape {
      appearance PBRAppearance {
        baseColor 1 0.0352941 0
        roughness 1
        metalness 0
      }
      geometry Box {
        size 5 0.1 0.5
      }
    }
  ]
  name "wall(2)"
}
Solid {
  translation 0.39528 -0.412485 0
  rotation 0 1 0 0
  children [
    Group {
      children [
        Shape {
          appearance PBRAppearance {
            baseColor 0.65098 1 0.419608
            roughness 1
            metalness 0
          }
          geometry Cylinder {
            height 0.1
            radius 0.05
          }
        }
        Transform {
          translation 0.02 0.03 0.05
          scale 0.1 0.1 0.1
          children [
            Shape {
              appearance USE wallcolor
              geometry Sphere {
                radius 0.1
              }
            }
          ]
        }
        Transform {
          translation 0 -0.01 0.05
          scale 0.2 0.2 0.2
          children [
            Shape {
              appearance USE wallcolor
              geometry Sphere {
                radius 0.1
              }
            }
          ]
        }
      ]
    }
  ]
  name "dumbell"
}
Robot {
  translation -0.177265 0.0196086 0.05
  children [
    DEF body Shape {
      appearance PBRAppearance {
        baseColor 1 0.0627451 0.0784314
        metalness 0
      }
      geometry Box {
        size 0.1 0.2 0.05
      }
    }
    HingeJoint {
      jointParameters HingeJointParameters {
        anchor 0.06 0 0.05
      }
      device [
        RotationalMotor {
          name "wheels1"
        }
      ]
      endPoint Solid {
        translation 0.06 -0.06 -0.0020000000000000018
        rotation 0 1 0 1.55
        children [
          DEF wheel Shape {
            appearance PBRAppearance {
              baseColor 0.105882 1 0.0588235
              metalness 0
            }
            geometry Cylinder {
              height 0.02
              radius 0.035
            }
          }
        ]
        name "leftfront"
        boundingObject USE wheel
        physics DEF phsyc_wheel Physics {
        }
      }
    }
    HingeJoint {
      jointParameters HingeJointParameters {
        anchor -0.06 0 -0.05
      }
      device [
        RotationalMotor {
          name "wheels2"
        }
      ]
      endPoint Solid {
        translation -0.06 -0.06 -0.0020000000000000018
        rotation 0 1 0 1.55
        children [
          DEF wheel Shape {
            appearance PBRAppearance {
              baseColor 0.105882 1 0.0588235
              metalness 0
            }
            geometry Cylinder {
              height 0.02
              radius 0.035
            }
          }
        ]
        name "rightfront"
        boundingObject USE wheel
        physics DEF phsyc_wheel Physics {
        }
      }
    }
    HingeJoint {
      jointParameters HingeJointParameters {
        anchor 0.06 0 0.05
      }
      device [
        RotationalMotor {
          name "wheels3"
        }
      ]
      endPoint Solid {
        translation 0.0608316 0.0599912 0.0020000000000000018
        rotation 0 1 0 1.55
        children [
          USE wheel
        ]
        name "leftback"
        boundingObject USE wheel
        physics USE phsyc_wheel
      }
    }
    HingeJoint {
      jointParameters HingeJointParameters {
        anchor -0.06 0 -0.05
      }
      device [
        RotationalMotor {
          name "wheels4"
        }
      ]
      endPoint Solid {
        translation -0.0608316 0.0599912 0.0020000000000000018
        rotation 0 1 0 1.55
        children [
          USE wheel
        ]
        name "rightback"
        boundingObject USE wheel
        physics USE phsyc_wheel
      }
    }
    DistanceSensor {
      translation 0.03 -0.1 0.007
      rotation 0 1 0 1.27
      children [
        DEF sensor Shape {
          appearance PBRAppearance {
            baseColor 0 1 1
            metalness 0
          }
          geometry Box {
            size 0.01 0.01 0.01
          }
        }
      ]
      name "ds_left"
      boundingObject USE sensor
      physics Physics {
      }
    }
    DistanceSensor {
      translation -0.03 -0.1 0.007
      rotation 0 1 0 -1.27
      children [
        DEF sensor Shape {
          appearance PBRAppearance {
            baseColor 0 1 1
            metalness 0
          }
          geometry Box {
            size 0.01 0.01 0.01
          }
        }
      ]
      name "ds_right"
      boundingObject USE sensor
      physics Physics {
      }
    }
  ]
  boundingObject USE body
  physics Physics {
  }
  controller "4wheel_avoid_collision"
}
